Workbook

Sheet progress
A1: A URL has been suggested for
A2: =COUNTA('glossaryterms-export'!G1:G1091) -> 888 | B2: entries,
A3: =A2/1091 -> 0.81393217 | B3: of the way to completion
A5: A URL has been determined for
A6: =COUNTA('glossaryterms-export'!H1:H1091) -> 712 | B6: entries,
A7: =A6/1091 -> 0.65261228 | B7: of the way to completion

Sheet PrioritizedGlossaryTerms
A1: Rank # | B1: https://www.adl.org/resources/backgrounder/764 | C1: Page path and screen class | D1: Redirected | E1: Regex to match main sheet | F1: Finalized But Not RD'd? | G1: Views | H1: Active users | I1: Views per active user | J1: Average engagement time per active user | K1: Event count
A2: 1 | B2: https://www.adl.org/resources/backgrounder/qanon | C2: /glossary/frazzledrip/ | E2: =_xlfn.REGEXREPLACE(C2, "(.*)\/$", "https://extremismterms.adl.org\1") -> https://extremismterms.adl.org/glossary/frazzledrip | F2: {=_xlfn.LET(_xlpm.rowNum,MATCH(E2,'glossaryterms-export'!C:C,0), IF(AND(NOT(ISBLANK(INDEX('glossaryterms-export'!H:H,_xlpm.rowNum))),ISBLANK(INDEX('glossaryterms-export'!I:I,_xlpm.rowNum))),"Ready to Fix",""))} | G2: 261350 | H2: 226953 | I2: 1.15156 | J2: 34.766313 | K2: 1045389 | L2: =VLOOKUP(H2,'PrioritizedGlossaryTerms'!A2:C1066
A3: 2 | B3: https://www.adl.org/resources/article/qanon-adherents-reeling-wake-inauguration-trump-departure | C3: /glossary/nesaragesara/ | D3: Y | E3: =_xlfn.REGEXREPLACE(C3, "(.*)\/$", "https://extremismterms.adl.org\1") -> https://extremismterms.adl.org/glossary/nesaragesara | F3: {=_xlfn.LET(_xlpm.rowNum,MATCH(E3,'glossaryterms-export'!C:C,0), IF(AND(NOT(ISBLANK(INDEX('glossaryterms-export'!H:H,_xlpm.rowNum))),ISBLANK(INDEX('glossaryterms-export'!I:I,_xlpm.rowNum))),"Ready to Fix",""))} | G3: 134513 | H3: 108466 | I3: 1.2401398 | J3: 42.681651 | K3: 549621
A4: 3 | C4: /glossary/europa-last-battle/ | E4: =_xlfn.REGEXREPLACE(C4, "(.*)\/$", "https://extremismterms.adl.org\1") -> https://extremismterms.adl.org/glossary/europa-last-battle | F4: {=_xlfn.LET(_xlpm.rowNum,MATCH(E4,'glossaryterms-export'!C:C,0), IF(AND(NOT(ISBLANK(INDEX('glossaryterms-export'!H:H,_xlpm.rowNum))),ISBLANK(INDEX('glossaryterms-export'!I:I,_xlpm.rowNum))),"Ready to Fix",""))} | G4: 56498 | H4: 49567 | I4: 1.1398309 | J4: 15.081324 | K4: 223938
A5: 4 | B5: https://www.adl.org/resources/backgrounder/incels-involuntary-celibates | C5: /glossary/foid/ | D5: Y | E5: =_xlfn.REGEXREPLACE(C5, "(.*)\/$", "https://extremismterms.adl.org\1") -> https://extremismterms.adl.org/glossary/foid | F5: {=_xlfn.LET(_xlpm.rowNum,MATCH(E5,'glossaryterms-export'!C:C,0), IF(AND(NOT(ISBLANK(INDEX('glossaryterms-export'!H:H,_xlpm.rowNum))),ISBLANK(INDEX('glossaryterms-export'!I:I,_xlpm.rowNum))),"Ready to Fix",""))} | G5: 38723 | H5: 33619 | I5: 1.1518189 | J5: 13.212648 | K5: 143337
A6: 5 | C6: /glossary/fall-cabal/ | E6: =_xlfn.REGEXREPLACE(C6, "(.*)\/$", "https://extremismterms.adl.org\1") -> https://extremismterms.adl.org/glossary/fall-cabal | F6: {=_xlfn.LET(_xlpm.rowNum,MATCH(E6,'glossaryterms-export'!C:C,0), IF(AND(NOT(ISBLANK(INDEX('glossaryterms-export'!H:H,_xlpm.rowNum))),ISBLANK(INDEX('glossaryterms-export'!I:I,_xlpm.rowNum))),"Ready to Fix",""))} | G6: 36024 | H6: 31002 | I6: 1.1619895 | J6: 18.501032 | K6: 145611
A7: 6 | B7: https://www.adl.org/resources/backgrounder/sovereign-citizen-movement-united-states | C7: /glossary/civil-peace-flagcivil-flag-peacetime/ | D7: Y | E7: =_xlfn.REGEXREPLACE(C7, "(.*)\/$", "https://extremismterms.adl.org\1") -> https://extremismterms.adl.org/glossary/civil-peace-flagcivil-flag-peacetime | F7: {=_xlfn.LET(_xlpm.rowNum,MATCH(E7,'glossaryterms-export'!C:C,0), IF(AND(NOT(ISBLANK(INDEX('glossaryterms-export'!H:H,_xlpm.rowNum))),ISBLANK(INDEX('glossaryterms-export'!I:I,_xlpm.rowNum))),"Ready to Fix",""))} | G7: 19701 | H7: 16924 | I7: 1.1640865 | J7: 28.443512 | K7: 71568
A8: 7 | B8: https://www.adl.org/resources/backgrounder/qanon | C8: /glossary/q-drop/ | D8: Y | E8: =_xlfn.REGEXREPLACE(C8, "(.*)\/$", "https://extremismterms.adl.org\1") -> https://extremismterms.adl.org/glossary/q-drop | F8: {=_xlfn.LET(_xlpm.rowNum,MATCH(E8,'glossaryterms-export'!C:C,0), IF(AND(NOT(ISBLANK(INDEX('glossaryterms-export'!H:H,_xlpm.rowNum))),ISBLANK(INDEX('glossaryterms-export'!I:I,_xlpm.rowNum))),"Ready to Fix",""))} | G8: 17973 | H8: 15317 | I8: 1.1734021 | J8: 14.664556 | K8: 72878
A9: 8 | B9: https://adl.org/resources/backgrounder/groyper-army-and-america-first | C9: /glossary/america-first/ | D9: Y | E9: =_xlfn.REGEXREPLACE(C9, "(.*)\/$", "https://extremismterms.adl.org\1") -> https://extremismterms.adl.org/glossary/america-first | F9: {=_xlfn.LET(_xlpm.rowNum,MATCH(E9,'glossaryterms-export'!C:C,0), IF(AND(NOT(ISBLANK(INDEX('glossaryterms-export'!H:H,_xlpm.rowNum))),ISBLANK(INDEX('glossaryterms-export'!I:I,_xlpm.rowNum))),"Ready to Fix",""))} | G9: 13745 | H9: 10547 | I9: 1.3032142 | J9: 22.075567 | K9: 49684
A10: 9 | B10: https://www.adl.org/resources/article/israel-hamas-ceasefire-sparks-fresh-wave-antisemitism-support-terror-us-anti | C10: /glossary/inverted-red-triangle/ | E10: =_xlfn.REGEXREPLACE(C10, "(.*)\/$", "https://extremismterms.adl.org\1") -> https://extremismterms.adl.org/glossary/inverted-red-triangle | F10: {=_xlfn.LET(_xlpm.rowNum,MATCH(E10,'glossaryterms-export'!C:C,0), IF(AND(NOT(ISBLANK(INDEX('glossaryterms-export'!H:H,_xlpm.rowNum))),ISBLANK(INDEX('glossaryterms-export'!I:I,_xlpm.rowNum))),"Ready to Fix",""))} | G10: 10513 | H10: 9359 | I10: 1.1233038 | J10: 26.462763 | K10: 56127
A11: 10 | B11: https://www.adl.org/resources/backgrounder/qanon | C11: /glossary/ncswic-nothing-can-stop-what-coming/ | D11: Y | E11: =_xlfn.REGEXREPLACE(C11, "(.*)\/$", "https://extremismterms.adl.org\1") -> https://extremismterms.adl.org/glossary/ncswic-nothing-can-stop-what-coming | F11: {=_xlfn.LET(_xlpm.rowNum,MATCH(E11,'glossaryterms-export'!C:C,0), IF(AND(NOT(ISBLANK(INDEX('glossaryterms-export'!H:H,_xlpm.rowNum))),ISBLANK(INDEX('glossaryterms-export'!I:I,_xlpm.rowNum))),"Ready to Fix",""))} | G11: 10426 | H11: 9154 | I11: 1.1389556 | J11: 17.279659 | K11: 41458
A12: 11 | B12: https://www.adl.org/resources/article/another-weekend-hate-neo-nazis-gather-florida | C12: /glossary/order-black-sun/ | E12: =_xlfn.REGEXREPLACE(C12, "(.*)\/$", "https://extremismterms.adl.org\1") -> https://extremismterms.adl.org/glossary/order-black-sun | F12: {=_xlfn.LET(_xlpm.rowNum,MATCH(E12,'glossaryterms-export'!C:C,0), IF(AND(NOT(ISBLANK(INDEX('glossaryterms-export'!H:H,_xlpm.rowNum))),ISBLANK(INDEX('glossaryterms-export'!I:I,_xlpm.rowNum))),"Ready to Fix",""))} -> Ready to Fix | G12: 8512 | H12: 7552 | I12: 1.1271186 | J12: 17.350106 | K12: 33054
A13: 12 | C13: /glossary/dumbs/ | E13: =_xlfn.REGEXREPLACE(C13, "(.*)\/$", "https://extremismterms.adl.org\1") -> https://extremismterms.adl.org/glossary/dumbs | F13: {=_xlfn.LET(_xlpm.rowNum,MATCH(E13,'glossaryterms-export'!C:C,0), IF(AND(NOT(ISBLANK(INDEX('glossaryterms-export'!H:H,_xlpm.rowNum))),ISBLANK(INDEX('glossaryterms-export'!I:I,_xlpm.rowNum))),"Ready to Fix",""))} | G13: 8429 | H13: 7382 | I13: 1.1418315 | J13: 24.283392 | K13: 34894
A14: 13 | B14: https://www.adl.org/resources/backgrounder/proud-boys | C14: /glossary/fuck-around-and-find-out-fafo/ | D14: Y | E14: =_xlfn.REGEXREPLACE(C14, "(.*)\/$", "https://extremismterms.adl.org\1") -> https://extremismterms.adl.org/glossary/fuck-around-and-find-out-fafo | F14: {=_xlfn.LET(_xlpm.rowNum,MATCH(E14,'glossaryterms-export'!C:C,0), IF(AND(NOT(ISBLANK(INDEX('glossaryterms-export'!H:H,_xlpm.rowNum))),ISBLANK(INDEX('glossaryterms-export'!I:I,_xlpm.rowNum))),"Ready to Fix",""))} | G14: 8128 | H14: 7141 | I14: 1.1382159 | J14: 23.247724 | K14: 32699
A15: 14 | B15: https://www.adl.org/resources/article/coded-hate-extremists-weaponize-seemingly-innocuous-content-promote-bigotry | C15: /glossary/noticing/ | D15: Y | E15: =_xlfn.REGEXREPLACE(C15, "(.*)\/$", "https://extremismterms.adl.org\1") -> https://extremismterms.adl.org/glossary/noticing | F15: {=_xlfn.LET(_xlpm.rowNum,MATCH(E15,'glossaryterms-export'!C:C,0), IF(AND(NOT(ISBLANK(INDEX('glossaryterms-export'!H:H,_xlpm.rowNum))),ISBLANK(INDEX('glossaryterms-export'!I:I,_xlpm.rowNum))),"Ready to Fix",""))} | G15: 7020 | H15: 5850 | I15: 1.2 | J15: 22.350256 | K15: 19678
A16: 15 | B16: https://www.adl.org/resources/backgrounder/sovereign-citizen-movement-united-states | C16: /glossary/david-straight/ | D16: Y | E16: =_xlfn.REGEXREPLACE(C16, "(.*)\/$", "https://extremismterms.adl.org\1") -> https://extremismterms.adl.org/glossary/david-straight | F16: {=_xlfn.LET(_xlpm.rowNum,MATCH(E16,'glossaryterms-export'!C:C,0), IF(AND(NOT(ISBLANK(INDEX('glossaryterms-export'!H:H,_xlpm.rowNum))),ISBLANK(INDEX('glossaryterms-export'!I:I,_xlpm.rowNum))),"Ready to Fix",""))} | G16: 6215 | H16: 5235 | I16: 1.1872015 | J16: 26.641261 | K16: 26040
A17: 16 | B17: https://www.adl.org/resources/article/coded-hate-extremists-weaponize-seemingly-innocuous-content-promote-bigotry | C17: /glossary/early-life-check/ | D17: Y | E17: =_xlfn.REGEXREPLACE(C17, "(.*)\/$", "https://extremismterms.adl.org\1") -> https://extremismterms.adl.org/glossary/early-life-check | F17: {=_xlfn.LET(_xlpm.rowNum,MATCH(E17,'glossaryterms-export'!C:C,0), IF(AND(NOT(ISBLANK(INDEX('glossaryterms-export'!H:H,_xlpm.rowNum))),ISBLANK(INDEX('glossaryterms-export'!I:I,_xlpm.rowNum))),"Ready to Fix",""))} -> Ready to Fix | G17: 6130 | H17: 5353 | I17: 1.1451523 | J17: 23.819727 | K17: 20403
A18: 17 | C18: /glossary/patriotswin/ | E18: =_xlfn.REGEXREPLACE(C18, "(.*)\/$", "https://extremismterms.adl.org\1") -> https://extremismterms.adl.org/glossary/patriotswin | F18: {=_xlfn.LET(_xlpm.rowNum,MATCH(E18,'glossaryterms-export'!C:C,0), IF(AND(NOT(ISBLANK(INDEX('glossaryterms-export'!H:H,_xlpm.rowNum))),ISBLANK(INDEX('glossaryterms-export'!I:I,_xlpm.rowNum))),"Ready to Fix",""))} | G18: 5954 | H18: 5011 | I18: 1.188186 | J18: 11.144482 | K18: 22856
A19: 18 | B19: https://www.adl.org/resources/article/coded-hate-extremists-weaponize-seemingly-innocuous-content-promote-bigotry | C19: /glossary/never-lose-your-smile/ | D19: Y | E19: =_xlfn.REGEXREPLACE(C19, "(.*)\/$", "https://extremismterms.adl.org\1") -> https://extremismterms.adl.org/glossary/never-lose-your-smile | F19: {=_xlfn.LET(_xlpm.rowNum,MATCH(E19,'glossaryterms-export'!C:C,0), IF(AND(NOT(ISBLANK(INDEX('glossaryterms-export'!H:H,_xlpm.rowNum))),ISBLANK(INDEX('glossaryterms-export'!I:I,_xlpm.rowNum))),"Ready to Fix",""))} | G19: 5932 | H19: 5191 | I19: 1.1427471 | J19: 22.255635 | K19: 18192
A20: 19 | B20: https://www.adl.org/resources/backgrounder/sovereign-citizen-movement-united-states | C20: /glossary/american-state-national/ | D20: Y | E20: =_xlfn.REGEXREPLACE(C20, "(.*)\/$", "https://extremismterms.adl.org\1") -> https://extremismterms.adl.org/glossary/american-state-national | F20: {=_xlfn.LET(_xlpm.rowNum,MATCH(E20,'glossaryterms-export'!C:C,0), IF(AND(NOT(ISBLANK(INDEX('glossaryterms-export'!H:H,_xlpm.rowNum))),ISBLANK(INDEX('glossaryterms-export'!I:I,_xlpm.rowNum))),"Ready to Fix",""))} | G20: 5885 | H20: 5092 | I20: 1.1557345 | J20: 28.530047 | K20: 24202
A21: 20 | C21: /glossary/brother-nathanael/ | E21: =_xlfn.REGEXREPLACE(C21, "(.*)\/$", "https://extremismterms.adl.org\1") -> https://extremismterms.adl.org/glossary/brother-nathanael | F21: {=_xlfn.LET(_xlpm.rowNum,MATCH(E21,'glossaryterms-export'!C:C,0), IF(AND(NOT(ISBLANK(INDEX('glossaryterms-export'!H:H,_xlpm.rowNum))),ISBLANK(INDEX('glossaryterms-export'!I:I,_xlpm.rowNum))),"Ready to Fix",""))} -> Ready to Fix | G21: 5831 | H21: 5110 | I21: 1.1410959 | J21: 29.717417 | K21: 30312
A22: 21 | C22: /glossary/betar-usa/ | E22: =_xlfn.REGEXREPLACE(C22, "(.*)\/$", "https://extremismterms.adl.org\1") -> https://extremismterms.adl.org/glossary/betar-usa | F22: {=_xlfn.LET(_xlpm.rowNum,MATCH(E22,'glossaryterms-export'!C:C,0), IF(AND(NOT(ISBLANK(INDEX('glossaryterms-export'!H:H,_xlpm.rowNum))),ISBLANK(INDEX('glossaryterms-export'!I:I,_xlpm.rowNum))),"Ready to Fix",""))} | G22: 5783 | H22: 4526 | I22: 1.2777287 | J22: 39.036456 | K22: 22396
A23: 22 | B23: https://www.adl.org/resources/article/terrorgram-collective-international-terrorists-promoting-violence-and-white | C23: /glossary/terrorgram/ | E23: =_xlfn.REGEXREPLACE(C23, "(.*)\/$", "https://extremismterms.adl.org\1") -> https://extremismterms.adl.org/glossary/terrorgram | F23: {=_xlfn.LET(_xlpm.rowNum,MATCH(E23,'glossaryterms-export'!C:C,0), IF(AND(NOT(ISBLANK(INDEX('glossaryterms-export'!H:H,_xlpm.rowNum))),ISBLANK(INDEX('glossaryterms-export'!I:I,_xlpm.rowNum))),"Ready to Fix",""))} -> Ready to Fix | G23: 5670 | H23: 4906 | I23: 1.1557277 | J23: 26.67713 | K23: 25551
A24: 23 | C24: /glossary/matt-forney/ | E24: =_xlfn.REGEXREPLACE(C24, "(.*)\/$", "https://extremismterms.adl.org\1") -> https://extremismterms.adl.org/glossary/matt-forney | F24: {=_xlfn.LET(_xlpm.rowNum,MATCH(E24,'glossaryterms-export'!C:C,0), IF(AND(NOT(ISBLANK(INDEX('glossaryterms-export'!H:H,_xlpm.rowNum))),ISBLANK(INDEX('glossaryterms-export'!I:I,_xlpm.rowNum))),"Ready to Fix",""))} -> Ready to Fix | G24: 5522 | H24: 4995 | I24: 1.1055055 | J24: 10.004404 | K24: 22388
A25: 24 | C25: /glossary/died-suddenly/ | E25: =_xlfn.REGEXREPLACE(C25, "(.*)\/$", "https://extremismterms.adl.org\1") -> https://extremismterms.adl.org/glossary/died-suddenly | F25: {=_xlfn.LET(_xlpm.rowNum,MATCH(E25,'glossaryterms-export'!C:C,0), IF(AND(NOT(ISBLANK(INDEX('glossaryterms-export'!H:H,_xlpm.rowNum))),ISBLANK(INDEX('glossaryterms-export'!I:I,_xlpm.rowNum))),"Ready to Fix",""))} | G25: 5182 | H25: 4489 | I25: 1.1543774 | J25: 20.714413 | K25: 20463
A26: 25 | C26: /glossary/turning-point-usa-tpusa/ | E26: =_xlfn.REGEXREPLACE(C26, "(.*)\/$", "https://extremismterms.adl.org\1") -> https://extremismterms.adl.org/glossary/turning-point-usa-tpusa | F26: {=_xlfn.LET(_xlpm.rowNum,MATCH(E26,'glossaryterms-export'!C:C,0), IF(AND(NOT(ISBLANK(INDEX('glossaryterms-export'!H:H,_xlpm.rowNum))),ISBLANK(INDEX('glossaryterms-export'!I:I,_xlpm.rowNum))),"Ready to Fix",""))} | G26: 4985 | H26: 4199 | I26: 1.1871874 | J26: 29.699214 | K26: 14359
A27: 26 | C27: /resources/article/qanon-glossary/ | E27: =_xlfn.REGEXREPLACE(C27, "(.*)\/$", "https://extremismterms.adl.org\1") -> https://extremismterms.adl.org/resources/article/qanon-glossary | F27: {=_xlfn.LET(_xlpm.rowNum,MATCH(E27,'glossaryterms-export'!C:C,0), IF(AND(NOT(ISBLANK(INDEX('glossaryterms-export'!H:H,_xlpm.rowNum))),ISBLANK(INDEX('glossaryterms-export'!I:I,_xlpm.rowNum))),"Ready to Fix",""))} | G27: 4733 | H27: 3857 | I27: 1.2271195 | J27: 85.933109 | K27: 34045
A28: 27 | B28: https://www.adl.org/resources/article/coded-hate-extremists-weaponize-seemingly-innocuous-content-promote-bigotry | C28: /glossary/271k/ | D28: Y | E28: =_xlfn.REGEXREPLACE(C28, "(.*)\/$", "https://extremismterms.adl.org\1") -> https://extremismterms.adl.org/glossary/271k | F28: {=_xlfn.LET(_xlpm.rowNum,MATCH(E28,'glossaryterms-export'!C:C,0), IF(AND(NOT(ISBLANK(INDEX('glossaryterms-export'!H:H,_xlpm.rowNum))),ISBLANK(INDEX('glossaryterms-export'!I:I,_xlpm.rowNum))),"Ready to Fix",""))} | G28: 4667 | H28: 4132 | I28: 1.1294773 | J28: 19.77759 | K28: 16311
A29: 28 | B29: https://www.adl.org/resources/backgrounder/christian-identity-movement | C29: /glossary/christian-identity/ | D29: Y | E29: =_xlfn.REGEXREPLACE(C29, "(.*)\/$", "https://extremismterms.adl.org\1") -> https://extremismterms.adl.org/glossary/christian-identity | F29: {=_xlfn.LET(_xlpm.rowNum,MATCH(E29,'glossaryterms-export'!C:C,0), IF(AND(NOT(ISBLANK(INDEX('glossaryterms-export'!H:H,_xlpm.rowNum))),ISBLANK(INDEX('glossaryterms-export'!I:I,_xlpm.rowNum))),"Ready to Fix",""))} | G29: 4627 | H29: 3871 | I29: 1.1952984 | J29: 36.0589 | K29: 12138
A30: 29 | C30: /glossary/false-flag/ | E30: =_xlfn.REGEXREPLACE(C30, "(.*)\/$", "https://extremismterms.adl.org\1") -> https://extremismterms.adl.org/glossary/false-flag | F30: {=_xlfn.LET(_xlpm.rowNum,MATCH(E30,'glossaryterms-export'!C:C,0), IF(AND(NOT(ISBLANK(INDEX('glossaryterms-export'!H:H,_xlpm.rowNum))),ISBLANK(INDEX('glossaryterms-export'!I:I,_xlpm.rowNum))),"Ready to Fix",""))} | G30: 4569 | H30: 3924 | I30: 1.1643731 | J30: 21.557594 | K30: 17061
A31: 30 | B31: https://www.adl.org/resources/backgrounder/blood-tribe | C31: /glossary/christopher-pohlhaus/ | D31: Y | E31: =_xlfn.REGEXREPLACE(C31, "(.*)\/$", "https://extremismterms.adl.org\1") -> https://extremismterms.adl.org/glossary/christopher-pohlhaus | F31: {=_xlfn.LET(_xlpm.rowNum,MATCH(E31,'glossaryterms-export'!C:C,0), IF(AND(NOT(ISBLANK(INDEX('glossaryterms-export'!H:H,_xlpm.rowNum))),ISBLANK(INDEX('glossaryterms-export'!I:I,_xlpm.rowNum))),"Ready to Fix",""))} -> Ready to Fix | G31: 4486 | H31: 3964 | I31: 1.1316852 | J31: 27.282291 | K31: 23341
A32: 31 | C32: /glossary/thomas-dalton/ | E32: =_xlfn.REGEXREPLACE(C32, "(.*)\/$", "https://extremismterms.adl.org\1") -> https://extremismterms.adl.org/glossary/thomas-dalton | F32: {=_xlfn.LET(_xlpm.rowNum,MATCH(E32,'glossaryterms-export'!C:C,0), IF(AND(NOT(ISBLANK(INDEX('glossaryterms-export'!H:H,_xlpm.rowNum))),ISBLANK(INDEX('glossaryterms-export'!I:I,_xlpm.rowNum))),"Ready to Fix",""))} | G32: 4362 | H32: 3646 | I32: 1.1963796 | J32: 44.75864 | K32: 25312
A33: 32 | C33: /glossary/whiteblack-hats/ | E33: =_xlfn.REGEXREPLACE(C33, "(.*)\/$", "https://extremismterms.adl.org\1") -> https://extremismterms.adl.org/glossary/whiteblack-hats | F33: {=_xlfn.LET(_xlpm.rowNum,MATCH(E33,'glossaryterms-export'!C:C,0), IF(AND(NOT(ISBLANK(INDEX('glossaryterms-export'!H:H,_xlpm.rowNum))),ISBLANK(INDEX('glossaryterms-export'!I:I,_xlpm.rowNum))),"Ready to Fix",""))} | G33: 4226 | H33: 3607 | I33: 1.1716108 | J33: 24.054893 | K33: 17304
A34: 33 | B34: https://www.adl.org/resources/article/coded-hate-extremists-weaponize-seemingly-innocuous-content-promote-bigotry | C34: /glossary/six-million-cookies/ | D34: Y | E34: =_xlfn.REGEXREPLACE(C34, "(.*)\/$", "https://extremismterms.adl.org\1") -> https://extremismterms.adl.org/glossary/six-million-cookies | F34: {=_xlfn.LET(_xlpm.rowNum,MATCH(E34,'glossaryterms-export'!C:C,0), IF(AND(NOT(ISBLANK(INDEX('glossaryterms-export'!H:H,_xlpm.rowNum))),ISBLANK(INDEX('glossaryterms-export'!I:I,_xlpm.rowNum))),"Ready to Fix",""))} | G34: 4085 | H34: 3592 | I34: 1.1372494 | J34: 16.657294 | K34: 14740
A35: 34 | C35: /glossary/traditionalist-catholicism/ | E35: =_xlfn.REGEXREPLACE(C35, "(.*)\/$", "https://extremismterms.adl.org\1") -> https://extremismterms.adl.org/glossary/traditionalist-catholicism | F35: {=_xlfn.LET(_xlpm.rowNum,MATCH(E35,'glossaryterms-export'!C:C,0), IF(AND(NOT(ISBLANK(INDEX('glossaryterms-export'!H:H,_xlpm.rowNum))),ISBLANK(INDEX('glossaryterms-export'!I:I,_xlpm.rowNum))),"Ready to Fix",""))} | G35: 3748 | H35: 3152 | I35: 1.1890863 | J35: 51.120241 | K35: 20868
A36: 35 | C36: /glossary/chemtrails/ | E36: =_xlfn.REGEXREPLACE(C36, "(.*)\/$", "https://extremismterms.adl.org\1") -> https://extremismterms.adl.org/glossary/chemtrails | F36: {=_xlfn.LET(_xlpm.rowNum,MATCH(E36,'glossaryterms-export'!C:C,0), IF(AND(NOT(ISBLANK(INDEX('glossaryterms-export'!H:H,_xlpm.rowNum))),ISBLANK(INDEX('glossaryterms-export'!I:I,_xlpm.rowNum))),"Ready to Fix",""))} | G36: 3703 | H36: 3309 | I36: 1.1190692 | J36: 24.314294 | K36: 15074
A37: 36 | B37: https://www.adl.org/resources/backgrounder/great-replacement-explainer | C37: /glossary/great-replacement-replacement-theory/ | D37: Y | E37: =_xlfn.REGEXREPLACE(C37, "(.*)\/$", "https://extremismterms.adl.org\1") -> https://extremismterms.adl.org/glossary/great-replacement-replacement-theory | F37: {=_xlfn.LET(_xlpm.rowNum,MATCH(E37,'glossaryterms-export'!C:C,0), IF(AND(NOT(ISBLANK(INDEX('glossaryterms-export'!H:H,_xlpm.rowNum))),ISBLANK(INDEX('glossaryterms-export'!I:I,_xlpm.rowNum))),"Ready to Fix",""))} -> Ready to Fix | G37: 3694 | H37: 3376 | I37: 1.0941943 | J37: 25.452903 | K37: 15087
A38: 37 | B38: https://www.adl.org/resources/backgrounder/qanon | C38: /glossary/wwg1wga/ | D38: Y | E38: =_xlfn.REGEXREPLACE(C38, "(.*)\/$", "https://extremismterms.adl.org\1") -> https://extremismterms.adl.org/glossary/wwg1wga | F38: {=_xlfn.LET(_xlpm.rowNum,MATCH(E38,'glossaryterms-export'!C:C,0), IF(AND(NOT(ISBLANK(INDEX('glossaryterms-export'!H:H,_xlpm.rowNum))),ISBLANK(INDEX('glossaryterms-export'!I:I,_xlpm.rowNum))),"Ready to Fix",""))} | G38: 3625 | H38: 3192 | I38: 1.1356516 | J38: 19.915727 | K38: 14228
A39: 38 | C39: /glossary/murder-seth-rich/ | E39: =_xlfn.REGEXREPLACE(C39, "(.*)\/$", "https://extremismterms.adl.org\1") -> https://extremismterms.adl.org/glossary/murder-seth-rich | F39: {=_xlfn.LET(_xlpm.rowNum,MATCH(E39,'glossaryterms-export'!C:C,0), IF(AND(NOT(ISBLANK(INDEX('glossaryterms-export'!H:H,_xlpm.rowNum))),ISBLANK(INDEX('glossaryterms-export'!I:I,_xlpm.rowNum))),"Ready to Fix",""))} | G39: 3162 | H39: 2848 | I39: 1.1102528 | J39: 20.57198 | K39: 12531
A40: 39 | C40: /glossary/ryan-j-murdough/ | E40: =_xlfn.REGEXREPLACE(C40, "(.*)\/$", "https://extremismterms.adl.org\1") -> https://extremismterms.adl.org/glossary/ryan-j-murdough | F40: {=_xlfn.LET(_xlpm.rowNum,MATCH(E40,'glossaryterms-export'!C:C,0), IF(AND(NOT(ISBLANK(INDEX('glossaryterms-export'!H:H,_xlpm.rowNum))),ISBLANK(INDEX('glossaryterms-export'!I:I,_xlpm.rowNum))),"Ready to Fix",""))} -> Ready to Fix | G40: 3160 | H40: 2599 | I40: 1.2158523 | J40: 21.276645 | K40: 11128
...

Sheet All ADL.org Backgrounders
A1: title | B1: nid | C1: url
A2: The "Kosher Tax" Hoax: Anti-Semitic Recipe for Hate | B2: 30698 | C2: https://adl.ddev.site/resources/backgrounder/kosher-tax-hoax-anti-semitic-recipe-hate
A3: Jewish "Control" of the Federal Reserve: A Classic Antisemitic Myth | B3: 30699 | C3: https://adl.ddev.site/resources/backgrounder/jewish-control-federal-reserve-classic-antisemitic-myth
A4: The International Jew: 1920s Antisemitism Revived Online | B4: 30700 | C4: https://adl.ddev.site/resources/backgrounder/international-jew-1920s-antisemitism-revived-online
A5: Brown v. Board of Education | B5: 30702 | C5: https://adl.ddev.site/resources/backgrounder/brown-v-board-education
A6: Civil Rights Act of 1964 | B6: 30703 | C6: https://adl.ddev.site/resources/backgrounder/civil-rights-act-1964
A7: The Council on American Islamic Relations (CAIR) | B7: 30704 | C7: https://www.adl.org/resources/backgrounder/council-american-islamic-relations-cair
A8: From "Little Rock Nine" to Today | B8: 30713 | C8: https://adl.ddev.site/resources/backgrounder/little-rock-nine-today
A9: Oath Keepers and Three %ers Part of Growing Anti-Government Movement | B9: 30717 | C9: https://adl.ddev.site/resources/backgrounder/oath-keepers-and-three-ers-part-growing-anti-government-movement
A10: Glossary of Key Terms and Events in Israel's History: Israeli-Arab / Israeli-Palestinian Conflict | B10: 30722 | C10: https://adl.ddev.site/resources/backgrounder/glossary-key-terms-and-events-israels-history-israeli-arab-israeli
A11: Farrakhan: In His Own Words | B11: 30728 | C11: https://adl.ddev.site/resources/backgrounder/farrakhan-his-own-words
A12: Blood Libel: A False, Incendiary Claim Against Jews | B12: 30729 | C12: https://adl.ddev.site/resources/backgrounder/blood-libel-false-incendiary-claim-against-jews
A13: Primer on the First Amendment & Religious Freedom | B13: 30732 | C13: https://adl.ddev.site/resources/backgrounder/primer-first-amendment-religious-freedom
... A213: Los hutÃ­es: una larga tradiciÃ³n de antisemitismo y odio a Israel | B213: 91807 | C213: https://www.adl.org/es/resources/backgrounder/los-huties-una-larga-tradicion-de-antisemitismo-y-odio-israel
A214: 764 | B214: 92206 | C214: https://www.adl.org/resources/backgrounder/764
A215: Plan Andinia | B215: 92372 | C215: https://adl.ddev.site/es/resources/backgrounder/plan-andinia
A216: Iranian Supreme Leader Ayatollah Khamenei In His Own Words | B216: 92705 | C216: https://adl.ddev.site/resources/backgrounder/iranian-supreme-leader-ayatollah-khamenei-his-own-words
A217: El lÃ­der supremo iranÃ­, el ayatolÃ¡ Jamenei, en sus propias palabras | B217: 92712 | C217: https://adl.ddev.site/es/resources/backgrounder/el-lider-supremo-irani-el-ayatola-jamenei-en-sus-propias-palabras
A218: Slogan: Free Palestine | B218: 92733 | C218: https://adl.ddev.site/resources/backgrounder/slogan-free-palestine
A219: Abraham Accords | B219: 92734 | C219: https://adl.ddev.site/resources/backgrounder/abraham-accords
A220: The International Union of Muslim Scholars (IUMS) in Its Own Words | B220: 92792 | C220: https://adl.ddev.site/resources/backgrounder/international-union-muslim-scholars-iums-its-own-words
A221: Eslogan: Palestina libre | B221: 92804 | C221: https://adl.ddev.site/es/resources/backgrounder/eslogan-palestina-libre
A222: Acuerdos de Abraham | B222: 92805 | C222: https://adl.ddev.site/es/resources/backgrounder/acuerdos-de-abraham
A223: The Party for Socialism and Liberation (PSL) | B223: 92842 | C223: https://www.adl.org/resources/backgrounder/party-socialism-and-liberation-psl
A224: Understanding and Countering Soft and Shadow Boycotts of Israel | B224: 93187 | C224: https://adl.ddev.site/resources/backgrounder/understanding-and-countering-soft-and-shadow-boycotts-israel
A225: Sobre la definiciÃ³n de trabajo del antisemitismo de la IHRA | B225: 93196 | C225: https://adl.ddev.site/es/resources/backgrounder/sobre-la-definicion-de-trabajo-del-antisemitismo-de-la-ihra
A226: Faculty and Staff for Justice in Palestine (FSJP) | B226: 93229 | C226: https://www.adl.org/resources/backgrounder/faculty-and-staff-justice-palestine-fsjp

Sheet glossaryterms-export
B1: Title | C1: URL | D1: Category | E1: Ideology | F1: Summary | G1: URL to be Redirected to (FL/Rebecca/SME First Pass) | H1: URL to be Redirected to (finalized) | I1: Redirect Put in Place? | J1: Notes | K1: PRIORITY | L1: Note
A2: 681 | B2: Looksmaxxing | C2: https://extremismterms.adl.org/glossary/looksmaxxing | D2: Tactics, Key Concepts / Definitions | E2: Single-issue | F2: Looksmaxxing refers to any attempts made by incels to improve upon their physical appearance. These strategies range from haircuts and new clothes, taking steroids and going to the gym all the way up to cosmetic surgery. | G2: https://www.adl.org/resources/backgrounder/incels-involuntary-celibates | H2: https://www.adl.org/resources/backgrounder/incels-involuntary-celibates | I2: Y | K2: low | L2: Incel/ misogyny terms/phrases
A3: 854 | B3: White supremacist (physical) propaganda | C3: https://extremismterms.adl.org/glossary/white-supremacist-physical-propaganda | D3: Tactics | E3: White supremacist, Right-wing, Antisemitism | F3: Physical white supremacist propaganda includes distributions of physical media like fliers, posters, stickers, leaflets, banners and graffiti. The goal is to maximize media and online attention, while limiting the risk of individual exposure, negative media coverage, arrests and public backlash that often accompany public white supremacist events.
A4: 49779 | B4: Q clock | C4: https://adl.org/glossary/q-clock | D4: Tactics | E4: Right-wing | F4: The Q clock is a tool used by QAnon followers to "prove" that Q has predicted future events. The Q clock consists of a standard clock surrounded by a line spiraling outwards, which features a series of dated points. Each point forms a "second" on the clock, and a shaded date indicates that Q posted a drop(s) on that date. To "read" the clock, QAnon followers draw a line from today's date on the spiral to the center of the clock, checking for any Q drops on shaded dates that the line intersects and decoding their meaning. The clock can also be "mirrored" by continuing to draw a line through to the other side of the clock, intersecting additional shaded dates and drops that can be decoded. The Q clock can only be used to confirm that Q predicted a future event in a prior drop; it cannot be used by QAnon followers to predict future events. | G4: https://www.adl.org/resources/backgrounder/qanon | H4: https://www.adl.org/resources/backgrounder/qanon | I4: Y | K4: low | L4: conspiracy (QAnon)
A5: 82979 | B5: Red ink thumbprints/fingerprints | C5: https://extremismterms.adl.org/glossary/red-ink-thumbprintsfingerprints | D5: Tactics | E5: Right Wing (Anti-Government) | F5: Some sovereign citizens believe they must place a thumbprint or fingerprint next to their signature on a document for it to be valid. Most, though not all, who hold such beliefs further claim that the signature and fingerprint must be in red ink.The origins of the sovereign citizen thumbprint idea date back to the late 1980s, though it only became popular in the 1990s. In some societies at some points in history, such prints were used as signatures or were required to accompany signatures.
A6: 71 | B6: Black Bloc Tactics | C6: https://extremismterms.adl.org/glossary/black-bloc-tactics | D6: Tactics | E6: Left-wing | F6: Black bloc tactics are often employed by militant antifa adherents at protests. Participants dressed in all black will operate as a unified force. Tactics include arming themselves with riot shields and positioning themselves at the front while others behind them move "like water." | G6: https://www.adl.org/resources/backgrounder/who-are-antifa | H6: https://www.adl.org/resources/backgrounder/who-are-antifa | K6: medium | L6: left wing terms/symbols
A7: 685 | B7: Media Jihad | C7: https://extremismterms.adl.org/glossary/media-jihad | D7: Tactics | E7: Islamist, Antisemitism | F7: "Media jihad" refers to an ISIS innovation in the Islamist terrorist sphere heavily emphasizing online media and appealing propaganda as a means of recruiting foreign fighters and spreading its message. To this end, ISIS recruiters often emphasize that "media jihad," creating and spreading ISIS propaganda online, is just as effective a method of supporting the caliphate as traveling to conflict zones.
A8: 700 | B8: Nutella and Kittens | C8: https://extremismterms.adl.org/glossary/nutella-and-kittens | D8: Tactics | E8: Islamist, Antisemitism | F8: Nutella and kittens was among ISIS's more inventive and disturbing media tactics. In 2015, the group paired calls to join the Islamic State with innocuous images that were popular on the internet, including pictures of kittens or jars of Nutella. One New Jersey-based ISIS recruiter even went by the online nickname "Umm Nutella," meaning "Mother of Nutella." Though it is unclear whether this tactic was effective at increasing recruitment, it generated a great deal of attention for ISIS online.
A9: 713 | B9: Paper Terrorism | C9: https://extremismterms.adl.org/glossary/paper-terrorism | D9: Tactics | E9: Anti-government, Right-wing | F9: "Paper terrorism" is a term given to a range of tactics developed by the sovereign citizen movement to use against their perceived enemies. These tactics typically involve the filing of bogus legal documents or the misuse of legal documents in a way designed to harass, retaliate against or harm police, government officials and others. Common paper terrorism tactics include bogus liens, false IRS 1099 forms, false involuntary bankruptcies and false criminal complaints, among others. | G9: https://www.adl.org/resources/backgrounder/sovereign-citizen-movement-united-states | H9: https://www.adl.org/resources/backgrounder/sovereign-citizen-movement-united-states | I9: Y | K9: Low | L9: sovereign citizen term (solution create an article with a list of sovereign citizen groups and terms?)
A10: 92203 | B10: Blood Signs / Blood Signing | C10: https://extremismterms.adl.org/glossary/blood-signs-blood-signing | D10: Tactics | F10: Blood signing refers to the practice of coercing a victim to write their abuser‚Äôs name or aliases on their own body or other surfaces using either their own blood or animal blood.¬†¬†764 members use ‚Äúblood signs‚Äù to demonstrate their ‚Äúownership‚Äù over their victim(s) and obtain further influence within the network. | G10: https://www.adl.org/resources/backgrounder/764 | H10: https://www.adl.org/resources/backgrounder/764 | I10: Y | K10: medium | L10: nihilistic term/activity
A11: 92202 | B11: Cut Signs / Cut Signing | C11: https://extremismterms.adl.org/glossary/cut-signs-cut-signing | D11: Tactics | F11: Cut signing refers to the practice of coercing a victim to carve their abuser‚Äôs name or aliases into their own bodies.764 members use ‚Äúcut signs‚Äù to demonstrate their ‚Äúownership‚Äù over their victim(s) and obtain further influence within the network. | G11: https://www.adl.org/resources/backgrounder/764 | H11: https://www.adl.org/resources/backgrounder/764 | I11: Y | K11: medium | L11: nihlistic term/activity
A12: 92204 | B12: Fan Signs / Fan Signing | C12: https://extremismterms.adl.org/glossary/fan-signs-fan-signing | D12: Tactics | F12: Fan signing refers to the practice of coercing a victim to write their abuser‚Äôs name or aliases on their own body. In some cases, victims may also be encouraged to vandalize private property with the abuser‚Äôs name.764 members use ‚Äúfan signs‚Äù to demonstrate their ‚Äúownership‚Äù over their victim(s) and obtain further influence within the network. | G12: https://www.adl.org/resources/backgrounder/764 | H12: https://www.adl.org/resources/backgrounder/764 | I12: Y | K12: medium | L12: nihlistic term/activity
A13: 92201 | B13: Lorebook | C13: https://extremismterms.adl.org/glossary/lorebook | D13: Tactics | F13: Lorebooks are digital archives compiled by 764 members to extort their victims. They often include sexually explicit content, images or videos of self-harm, private messages between the victim and their abuser and other personal information, such as the victim‚Äôs full name, address and relatives.764 members use lorebooks to extort their victims, threatening to share them with a victim‚Äôs family or friends unless their demands are met. Many of these lorebooks, which typically feature minors, are also posted publicly in 764 chats so that other members can harass the victim. | G13: https://www.adl.org/resources/backgrounder/764 | H13: https://www.adl.org/resources/backgrounder/764 | I13: Y | K13: medium | L13: nihlistic term/activity
A14: 566 | B14: 14/23 | C14: https://extremismterms.adl.org/glossary/1423 | D14: Slogans / Code words, Numbers / Symbols | E14: White supremacist, Right-wing, Antisemitism | F14: 14/23 is a numeric code associated with the Southern Brotherhood, a white supremacist prison gang in Alabama. Fourteen is a reference to the 14 words, and 23 refers to the 23 rules members must follow. | G14: https://www.adl.org/resources/hate-symbol/1423 | H14: https://www.adl.org/resources/hate-symbol/1423 | J14: Marilyn | K14: low | L14: in HATE SYMBOLS DATABASE (or add)
A15: 630 | B15: Bowl Gang /Bowlwaffen/Bowlwaffen Division/The Bowl Patrol | C15: https://extremismterms.adl.org/glossary/bowl-gang-bowlwaffenbowlwaffen-divisionthe-bowl-patrol | D15: Slogans / Code words, Numbers / Symbols | E15: White supremacist, Right-wing, Antisemitism | F15: "Bowl Gang," "Bowlwaffen," "Bowlwaffen Division," and "the Bowl Patrol" are phrases and symbology used by supporters of white supremacist Dylann Roof who was convicted of murdering nine African-Americans in a racially motivated shooting spree at the Emanuel African Methodist Episcopal Church in Charleston, South Carolina, in 2015. The "Bowl" references Roof"s bowl-shaped haircut. Accelerationist groups consider Dylann Roof a "saint" and idolize his murderous actions, calling for others to emulate his racist murders. | G15: https://www.adl.org/resources/backgrounder/accelerationism | H15: https://www.adl.org/resources/backgrounder/accelerationism | I15: Y | K15: low | L15: in HATE SYMBOLS DATABASE (or add)
A16: 563 | B16: 13/90 | C16: https://extremismterms.adl.org/glossary/1390 | D16: Slogans / Code words, Numbers / Symbols | E16: White supremacist, Right-wing | F16: 13/90 is a numeric code phrase used by white supremacists as a shorthand reference to a common racist claim about alleged Black violence. The number 13 refers to the purported percentage of the U.S. population that is Black. The number 90 is a fabricated "percentage" of violent crimes committed by Black people. | G16: https://www.adl.org/resources/hate-symbol/1352-1390 | H16: https://www.adl.org/resources/hate-symbol/1352-1390 | J16: Marilyn | K16: low | L16: in HATE SYMBOLS DATABASE (or add)
A17: 813 | B17: The Great Awakening | C17: https://extremismterms.adl.org/glossary/great-awakening | D17: Slogans / Code words, Key Concepts / Definitions, Conspiracy Theories | E17: White supremacist, Right-wing, Antisemitism | F17: "The Great Awakening" refers to Q's dissemination of information, which began in October 2017. QAnon adherents believe that they are part of a vast intelligence operation designed to slowly awaken the American people to the truth about the Deep State. | G17: https://www.adl.org/resources/backgrounder/qanon | H17: https://www.adl.org/resources/backgrounder/qanon | I17: Y | L17: conspiracy
A18: 649 | B18: Day of the Rope | C18: https://extremismterms.adl.org/glossary/day-rope | D18: Slogans / Code words, Key Concepts / Definitions | E18: White supremacist, Right-wing, Antisemitism | F18: Day of the Rope is a white supremacist concept that draws on fictional mass murders of "race traitors" in The Turner Diaries. The phrase is sometimes shortened to a hashtag or "dotr," or written out as "The Day of the Rope is coming" to convey a threat of white revolution or targeted violence. | G18: https://www.adl.org/resources/hate-symbol/day-rope | H18: https://www.adl.org/resources/hate-symbol/day-rope | K18: low | L18: in HATE SYMBOLS DATABASE (or add)
A19: 742 | B19: Race traitor | C19: https://extremismterms.adl.org/glossary/race-traitor | D19: Slogans / Code words, Key Concepts / Definitions | E19: White supremacist, Right-wing, Antisemitism | F19: "Race traitor" is a term used by white supremacists to refer to people involved in multi-racial relationships, as well as other white people perceived by white supremacists to be acting against the best interests of the white race. | K19: low | L19: in HATE SYMBOLS DATABASE (or add)
A20: 743 | B20: Racial Holy War/RAHOWA | C20: https://extremismterms.adl.org/glossary/racial-holy-warrahowa | D20: Slogans / Code words, Key Concepts / Definitions | E20: White supremacist, Right-wing, Antisemitism | F20: RAHOWA is an acronym for "Racial Holy War" created by the Creativity Movement, a white supremacist pseudo-religion, as a rallying cry for the white supremacist cause. | G20: https://www.adl.org/resources/hate-symbol/rahowa | H20: https://www.adl.org/resources/hate-symbol/rahowa | K20: low | L20: in HATE SYMBOLS DATABASE (or add)
A21: 639 | B21: Chad | C21: https://extremismterms.adl.org/glossary/chad | D21: Slogans / Code words, Key Concepts / Definitions | E21: Single-issue | F21: Chad is a term referring to the archetypal "anti-incel:" a white, straight male with Aryan features and other "desirable" physical traits. Chads are simultaneously despised and revered by incels who believe that all women inherently desire these men. | G21: https://www.adl.org/resources/backgrounder/incels-involuntary-celibates | H21: https://www.adl.org/resources/backgrounder/incels-involuntary-celibates | I21: Y
A22: 43297 | B22: Grooming/Groomers | C22: https://extremismterms.adl.org/glossary/groominggroomers | D22: Slogans / Code words, Key Concepts / Definitions | E22: Single-issue | F22: Grooming refers to behaviors used by abusers to build relationships and trust with children or young people to aid in manipulating, exploiting and abusing them. The term has been appropriated and weaponized by anti-LGBTQ+ bigots who falsely imply or claim that members of the LGBTQ+ community are pedophiles and are ‚Äúgrooming‚Äù children by discussing issues related to sexual orientation and gender identity. | G22: https://www.adl.org/resources/article/what-grooming-truth-behind-dangerous-bigoted-lie-targeting-lgbtq-community | H22: https://www.adl.org/resources/article/what-grooming-truth-behind-dangerous-bigoted-lie-targeting-lgbtq-community
A23: 839 | B23: Volcel | C23: https://extremismterms.adl.org/glossary/volcel | D23: Slogans / Code words, Key Concepts / Definitions | E23: Single-issue | F23: Also known as "fakecel," the term "volcel" is used within the incel subculture to describe a person who is voluntarily celibate and therefore does not fit the criteria to be an incel. | G23: https://www.adl.org/resources/backgrounder/incels-involuntary-celibates | H23: https://www.adl.org/resources/backgrounder/incels-involuntary-celibates | I23: Y | K23: low | L23: Incel/ misogyny terms/phrases
A24: 68856 | B24: Cultural Marxism | C24: https://extremismterms.adl.org/glossary/cultural-marxism | D24: Slogans / Code words, Key Concepts / Definitions | E24: Right-wing | F24: ‚ÄúCultural Marxism‚Äù is a term used typically by right-wing ideologues to attack an array of ideas and concepts they oppose, including multiculturalism, globalism, feminism and LGBTQ+ rights, among others. The term often functions as an antisemitic dog whistle or codeword. Promoters of the term typically invoke a conspiracy theory that falsely claims such progressive ideas originated with the so-called Frankfurt School, a leftist intellectual collective active in Germany between the two World Wars. Exploiting the fact that a number of the Frankfurt School intellectuals were Jewish, antisemitic versions of this conspiracy theory link the Frankfurt School, and thus ‚Äúcultural Marxism‚Äù itself, to Jews, claiming that Jews seek to subvert and weaken Western (and Christian) society by imposing their left-wing and politically correct (or ‚Äúwoke‚Äù) views. Antisemites also use the term to reinforce their longstanding antisemitic trope that Communism is ‚ÄúJewish.‚Äù
A25: 844 | B25: Western Chauvinism | C25: https://extremismterms.adl.org/glossary/western-chauvinism | D25: Slogans / Code words, Key Concepts / Definitions | E25: Right-wing | F25: Western chauvinism is a term that emphasizes the unabashed embrace and belief in the superiority of the western world, with an ethnocentric focus on maintaining a "western culture." Members of the Proud Boys often refer to themselves as "western chauvinists," and part of the Proud Boys' indoctrination ritual includes the use of the phrase, "I am a proud western chauvinist and I refuse to apologize for creating the modern world." | G25: https://www.adl.org/resources/backgrounder/proud-boys | H25: https://www.adl.org/resources/backgrounder/proud-boys | I25: Y
A26: 91823 | B26: Zionist Entity | C26: https://extremismterms.adl.org/glossary/zionist-entity | D26: Slogans / Code words, Key Concepts / Definitions | E26: Left Wing, Islamist | F26: ‚ÄúZionist entity‚Äù is a derogatory term for Israel designed to deny Israel‚Äôs legitimacy. The term emerged by the 1960s, used by Arab leaders in the Middle East who needed to refer to Israel but did not want to acknowledge its existence as a nation. Instead, they referred to Israel using language such as ‚Äúthe Zionist entity existing in Palestine.‚Äù Opponents of Israel continue to use the term today. In May 2025, after a gunman killed two Israeli Embassy staff members in Washington, D.C., Masar Badil‚Äîa transnational anti-Israel organization with ties to the terror-affiliated group Samidoun‚Äîresponded by saying that the attack was ‚Äúa natural consequence of the Zionist entity‚Äôs crimes in the Gaza Strip.‚Äù¬†The term ‚ÄúZionist entity‚Äù has spread to opponents and detractors of Israel more broadly, including within the United States. Usage of the term in the United States began as early as 1970. Today, it is primarily used by far left and anti-Israel groups and individuals, such as Students for Justice in Palestine, Within Our Lifetime, Palestinian Youth Movement, and PAL-Awda. Abroad, the term has also frequently been used by Iran‚Äôs Supreme Leader Ali Khamenei and other regime officials, as well as by the former leader of the terrorist group Hezbollah, Hassan Nasrallah. | G26: Mentioned and defined sort of here: https://www.adl.org/resources/article/healthcare-workers-palestine-hcw4p-what-you-need-know
A27: 799 | B27: Synagogue of Satan | C27: https://extremismterms.adl.org/glossary/synagogue-satan | D27: Slogans / Code words, Key Concepts / Definitions | E27: Antisemitism | F27: "Synagogue of Satan" is a derogatory term used by various antisemites ‚Äî such as the Nation of Islam, extremist sects of the Black Hebrew Israelite movement and many extremists who identify as Christians ‚Äî to refer to Jews and Judaism. The phrase is a reference to Revelation 2:9 and 3:9 in the Bible. | G27: No alternative source (MLM) | K27: priority | L27: antisemitic term/symbol/conspiracy
A28: 77 | B28: Blue-Eyed Devils | C28: https://extremismterms.adl.org/glossary/blue-eyed-devils | D28: Slogans / Code words, Groups / Movements | E28: White supremacist, Right-wing, Antisemitism | F28: The term "blue-eyed devil" is a racial epithet that originated in Asia, directed against people of European ancestry. Some white supremacists have adopted the term in recent decades and may refer to themselves as blue-eyed devils. A mid-1990s white power/Rock Against Communism (RAC) band from Delaware was also named Blue-Eyed Devils. The band is held in high regards by fellow white supremacists; many get tattoos of the band's distinctive logo, which is a man pointing a gun out of a rounded Celtic cross. | G28: https://www.adl.org/resources/hate-symbol/blue-eyed-devils | H28: https://www.adl.org/resources/hate-symbol/blue-eyed-devils | K28: low | L28: in HATE SYMBOLS DATABASE (or add)
A29: 773 | B29: Save the/our Children | C29: https://extremismterms.adl.org/glossary/save-theour-children | D29: Slogans / Code words, Conspiracy Theories, Key Concepts / Definitions | E29: Right-wing | F29: "Save the children" is a QAnon rallying cry often used as a hashtag on social media. QAnon borrowed this hashtag from a legitimate human-trafficking campaign to spread the baseless claim that pedophiles are kidnapping children off the streets and that mole/tunnel children are trafficked underground. Concerned people then spread the message using the hashtag, often unaware they are spreading a QAnon conspiracy. | G29: https://www.adl.org/resources/backgrounder/qanon | H29: https://www.adl.org/resources/backgrounder/qanon | I29: Y | K29: low | L29: conspiracy (QAnon)
A30: 867 | B30: Z.O.G. (Zionist Occupied Government) | C30: https://extremismterms.adl.org/glossary/zog-zionist-occupied-government | D30: Slogans / Code words, Conspiracy Theories | E30: White supremacist, Right-wing, Antisemitism | F30: Z.O.G. is an antisemitic acronym for "Zionist Occupied Government," which reflects the belief, often held by white supremacists and other antisemitic conspiracy theorists, that the U.S. government is controlled by Jews. This has resulted in white supremacist slogans such as "Smash ZOG," "Kill ZOG" and "Death to ZOG." | G30: https://www.adl.org/resources/hate-symbol/zog | H30: https://www.adl.org/resources/hate-symbol/zog | I30: Y | K30: priority | L30: antisemitic term/symbol/conspiracy
A31: 569 | B31: 17Anon | C31: https://extremismterms.adl.org/glossary/17anon | D31: Slogans / Code words, Conspiracy Theories | E31: Right-wing | F31: 17Anon is another name for QAnon, as Q is the seventeenth letter of the alphabet. The phrase is used to bypass blocking algorithms on social media. | G31: https://www.adl.org/resources/backgrounder/qanon | H31: https://www.adl.org/resources/backgrounder/qanon | I31: Y | J31: 17Anon is not mentioned in the QAnon backgrounder and should be added. Marilyn
A32: 740 | B32: Q sent me/us | C32: https://extremismterms.adl.org/glossary/q-sent-meus | D32: Slogans / Code words, Conspiracy Theories | E32: Right-wing | F32: "Q sent me" or "Q sent us" is a phrase used by QAnon adherents to express their allegiance to Q and their association with the army of digital soldiers. | G32: https://www.adl.org/resources/backgrounder/qanon | H32: https://www.adl.org/resources/backgrounder/qanon | I32: Y | K32: low | L32: conspiracy (QAnon)
A33: 3 | B33: "Pestilence from Heaven" | C33: https://extremismterms.adl.org/glossary/pestilence-heaven | D33: Slogans / Code words, Conspiracy Theories | E33: Antisemitism | F33: "Pestilence from Heaven" is a phrase used by the Nation of Islam to describe the coronavirus pandemic, with some specifically blaming Jews and Israel for causing the "pestilence." | G33: https://www.adl.org/resources/profile/nation-islam | H33: https://www.adl.org/resources/profile/nation-islam | J33: Marilyn
A34: 2 | B34: "Good Habits Bad Boys" | C34: https://extremismterms.adl.org/glossary/good-habits-bad-boys | D34: Slogans / Code words | E34: White supremacist, Right-wing, Antisemitism | F34: "Good habits bad boys" is the unofficial slogan of the Rise Above Movement (R.A.M.). It is often used in R.A.M. and R.A.M.-affilitated propaganda and clothing. | G34: https://www.adl.org/resources/backgrounder/rise-above-movement-ram | H34: https://www.adl.org/resources/backgrounder/rise-above-movement-ram | I34: Y | J34: Although this term is associated with the Rise Above Movement, it isn't in the current backgrounder and will have to be added. Marilyn | K34: low | L34: in HATE SYMBOLS DATABASE (or add)
A35: 4 | B35: "White Boy Summer" | C35: https://extremismterms.adl.org/glossary/white-boy-summer | D35: Slogans / Code words | E35: White supremacist, Right-wing, Antisemitism | F35: "White Boy Summer" was originally a Chet Hanks song released in March 2021, but was co-opted by white supremacists for their own purposes by layering on exclusionary messaging and using it as a call for action. | G35: https://www.adl.org/resources/article/white-boy-summer-meme-mobilization | H35: https://www.adl.org/resources/article/white-boy-summer-meme-mobilization | J35: Marilyn | K35: low | L35: in HATE SYMBOLS DATABASE (or add)
A36: 865 | B36: "You will not replace us" | C36: https://extremismterms.adl.org/glossary/you-will-not-replace-us | D36: Slogans / Code words | E36: White supremacist, Right-wing, Antisemitism | F36: "You will not replace us" is a slogan used by white supremacists that reflects the belief that without immediate action, the white race is doomed to extinction by an alleged "rising tide of color" purportedly controlled and manipulated by Jews. It is also a substitute for the "14 words" white supremacist motto. | G36: https://www.adl.org/resources/hate-symbol/you-will-not-replace-us | H36: https://www.adl.org/resources/hate-symbol/you-will-not-replace-us | J36: Marilyn | K36: low | L36: in HATE SYMBOLS DATABASE (or add)
A37: 565 | B37: 14 words | C37: https://extremismterms.adl.org/glossary/14-words | D37: Slogans / Code words | E37: White supremacist, Right-wing, Antisemitism | F37: 14 words is a popular white supremacist slogan penned by white supremacist and convicted terrorist David Lane: "We must secure the existence of our people and a future for white children.' | G37: https://www.adl.org/resources/hate-symbol/14-words | H37: https://www.adl.org/resources/hate-symbol/14-words | J37: Marilyn | K37: low | L37: in HATE SYMBOLS DATABASE (or add)
A38: 574 | B38: 23 (Hand Sign) | C38: https://extremismterms.adl.org/glossary/23-hand-sign | D38: Slogans / Code words | E38: White supremacist, Right-wing, Antisemitism | F38: This hand sign, in which one hand shows two fingers, and the other three, represents the number 23. Some white supremacists use this hand sign to represent the 23rd letter of the alphabet: W for white. | G38: https://www.adl.org/resources/hate-symbol/23-hand-sign | H38: https://www.adl.org/resources/hate-symbol/23-hand-sign | J38: Marilyn | K38: low | L38: in HATE SYMBOLS DATABASE (or add)
A39: 6 | B39: 6 Million Wasn't Enough (6MWE) | C39: https://extremismterms.adl.org/glossary/6-million-wasnt-enough-6mwe | D39: Slogans / Code words | E39: White supremacist, Right-wing, Antisemitism | F39: 6 Million Wasn't Enough (sometimes abbreviated to 6MWE) is an antisemitic phrase used by white supremacists which laments that only six million Jews murdered during the Holocaust. | G39: https://www.adl.org/resources/article/proud-boys-bigotry-full-display | H39: No resource outside Glossary (MLM) | J39: We could link here: https://www.adl.org/resources/article/proud-boys-bigotry-full-display, which references the term, but the term itself is not explicitly Proud Boys (MLM). | K39: priority | L39: add to innocuous phrase article
A40: 585 | B40: ACAB (All Cops Are Bastards) | C40: https://extremismterms.adl.org/glossary/acab-all-cops-are-bastards | D40: Slogans / Code words | E40: White supremacist, Right-wing, Antisemitism | F40: The acronym ACAB stands for 'All Cops Are Bastards' and is a slogan of long standing within skinhead subculture, which borrowed it from the punk subculture. Because non-racist skinheads (including "traditional" skinheads and anti-racist skinheads) may use this acronym as well as racist skinheads, it should be carefully judged in the context in which it appears. | G40: https://www.adl.org/resources/hate-symbol/acab | H40: https://www.adl.org/resources/hate-symbol/acab | J40: Marilyn | K40: low | L40: in HATE SYMBOLS DATABASE (or add)
...
